<?xml version="1.0" encoding="UTF-8"?>
<robot name="visual">

	<material name="blue">
		<color rgba="0 0 1 1"/>
	</material>
	<material name="black">
		<color rgba="0 0 0 1"/>
	</material>
	<material name="white">
		<color rgba="1 1 1 1"/>
	</material>

	<!--лидар -->
	<link name="lidar_link">
		<pose relative_to="floor2">0 0 0.03 0 0 0</pose>
		<inertial>
		<mass>0.2</mass>
		<inertia>
			<ixx>0.001</ixx>
			<ixy>0</ixy>
			<ixz>0</ixz>
			<iyy>0.001</iyy>
			<iyz>0</iyz>
			<izz>0.001</izz>
		</inertia>
		</inertial>
		<visual name="lidar_visual">
		<geometry>
			<cylinder>
			<radius>0.035</radius>
			<length>0.05</length>
			</cylinder>
		</geometry>
		<material>
			<ambient>0 0 0 1</ambient>
			<diffuse>0 0 0 1</diffuse>
		</material>
		</visual>
		<sensor name="lidar_sensor" type="gpu_ray">
		<frame_id>lidar_link</frame_id>
		<pose>0 0 0 0 0 0</pose>
		<topic>/lidar</topic>
		<update_rate>1</update_rate>
		<ray>
			<scan>
			<horizontal>
				<samples>36</samples>
				<resolution>1</resolution>
				<min_angle>-1.5708</min_angle> <!-- -90° -->
				<max_angle>1.5708</max_angle>  <!-- +90° -->
			</horizontal>
			<vertical>
				<samples>1</samples>
				<resolution>0.01</resolution>
				<min_angle>0</min_angle>
				<max_angle>0</max_angle>
			</vertical>
			</scan>
			<range>
			<min>0.08</min>
			<max>2.0</max>
			<resolution>0.01</resolution>
			</range>
			<noise>
			<type>gaussian</type>
			<mean>0.0</mean>
			<stddev>0.01</stddev>
			</noise>
		</ray>
		<always_on>true</always_on>
		<visualize>true</visualize>
		</sensor>
		<collision name="lidar_collision">
		<geometry>
			<cylinder>
			<radius>0.035</radius>
			<length>0.05</length>
			</cylinder>
		</geometry>
		</collision>
	</link>

	<!-- Фиксированный шарнир между базой и лидаром -->
	<joint name="lidar_joint" type="fixed">
	<parent link="base_link"/>
	<child link="lidar_link"/>
	<!-- Смещение (xyz) и ориентация (rpy) лидара относительно base_link -->
	<origin xyz="0 0 0.2" rpy="0 0 0"/>
	</joint>

	<!-- Odom link (корень без инерции) -->
	<link name="odom"/>

	<!-- Основная платформа (с инерцией) -->
	<link name="base_link">
		<visual>
			<geometry>
				<box size="0.2 0.23 0.005"/>
			</geometry>
			<material name="black"/>
		</visual>
		<collision>
			<geometry>
				<box size="0.2 0.23 0.005"/>
			</geometry>
		</collision>
		<inertial>
			<mass value="10"/>
			<inertia ixx="1e-3" ixy="0" ixz="0"
			         iyy="1e-3" iyz="0" izz="1e-3"/>
		</inertial>
	</link>

	<joint name="base_link_joint" type="fixed">
		<parent link="odom"/>
		<child link="base_link"/>
		<origin xyz="0 0 0" rpy="0 0 0"/>
	</joint>

	<!-- Промежуточное звено (left_base) -->
	<link name="left_base">
		<visual>
			<geometry>
				<box size="0.01 0.01 0.01"/>
			</geometry>
		</visual>
	</link>

	<joint name="left_base_joint" type="fixed">
		<parent link="base_link"/>
		<child link="left_base"/>
		<!-- Joint находится в позиции оси колеса -->
		<origin xyz="0.05 0.13 0"/>
	</joint>

	<!-- Левое колесо -->
	<link name="left_wheel">
		<visual>
			<origin rpy="1.57075 0 0" xyz="0 0 0"/>
			<geometry>
				<cylinder length="0.025" radius="0.0325"/>
			</geometry>
			<material name="blue"/>
		</visual>
		<collision>
			<origin rpy="1.57075 0 0" xyz="0 0 0"/>
			<geometry>
				<cylinder length="0.025" radius="0.0325"/>
			</geometry>
		</collision>
		<inertial>
			<mass value="1"/>
			<inertia ixx="1e-3" ixy="0" ixz="0"
			         iyy="1e-3" iyz="0" izz="1e-3"/>
		</inertial>
	</link>

	<joint name="left_wheel_joint" type="continuous">
		<axis xyz="0 1 0"/>
		<parent link="left_base"/>
		<child link="left_wheel"/>
		<!-- Колесо на нулевой позиции относительно промежуточного звена -->
		<origin xyz="0 0 0" rpy="0 0 0"/>
		<command_interface name="velocity"/><!-- управляем скорость колеса -->
		<state_interface name="position"/><!-- состояние: пройденный угол -->
		<state_interface name="velocity"/><!-- состояние: текущая скорость -->
	</joint>


	<!-- Промежуточное звено (right_base) -->
	<link name="right_base">
		<visual>
			<geometry>
				<box size="0.01 0.01 0.01"/>
			</geometry>
		</visual>
	</link>

	<joint name="right_base_joint" type="fixed">
		<parent link="base_link"/>
		<child link="right_base"/>
		<!-- Joint находится в позиции оси колеса -->
		<origin xyz="0.05 -0.13 0"/>
	</joint>

	<!-- Правое колесо -->
	<link name="right_wheel">
		<visual>
			<origin rpy="1.57075 0 0" xyz="0 0 0"/>
			<geometry>
				<cylinder length="0.025" radius="0.0325"/>
			</geometry>
			<material name="blue"/>
		</visual>
		<collision>
			<origin rpy="1.57075 0 0" xyz="0 0 0"/>
			<geometry>
				<cylinder length="0.025" radius="0.0325"/>
			</geometry>
		</collision>
		<inertial>
			<mass value="1"/>
			<inertia ixx="1e-3" ixy="0" ixz="0"
			         iyy="1e-3" iyz="0" izz="1e-3"/>
		</inertial>
	</link>

	<joint name="right_wheel_joint" type="continuous">
		<axis xyz="0 1 0"/>
		<parent link="right_base"/>
		<child link="right_wheel"/>
		<!-- Колесо на нулевой позиции относительно промежуточного звена -->
		<origin xyz="0 0 0" rpy="0 0 0"/>
		<command_interface name="velocity"/><!-- управляем скорость колеса -->
		<state_interface name="position"/><!-- состояние: пройденный угол -->
		<state_interface name="velocity"/><!-- состояние: текущая скорость -->
	</joint>


	<link name="caster_wheel">
		<visual>
			<origin xyz="0 0 0" rpy="0 0 0"/>
			<geometry>
				<sphere radius="0.015"/>
			</geometry>
			<material name="white"/>
		</visual>
		<collision>
			<origin xyz="0 0 0" rpy="0 0 0"/>
			<geometry>
				<sphere radius="0.015"/>
			</geometry>
		</collision>
		<inertial>
			<mass value="0.1"/>
			<inertia ixx="1e-4" ixy="0" ixz="0"
			         iyy="1e-3" iyz="0" izz="1e-3"/>
		</inertial>
	</link>

	<joint name="caster_wheel_joint" type="fixed">
		<parent link="base_link"/>
		<child link="caster_wheel"/>
		<origin xyz="-0.09 0 -0.01"/>
	</joint>

	<ros2_control name="my_robot_hardware" type="system">
		<hardware>
			<!-- Подключаем эмуляцию аппаратной части: GenericSystem с вычислением динамики -->
			<plugin>mock_components/GenericSystem</plugin>
			<param name="update_rate" type="int">50</param>
			<param name="calculate_dynamics" type="bool">true</param>
		</hardware>
		<!-- Описание управляемых шарниров -->
		<joint name="left_wheel_joint">
			<command_interface name="velocity"/><!-- управляем скорость колеса -->
			<state_interface name="position"/><!-- состояние: пройденный угол -->
			<state_interface name="velocity"/><!-- состояние: текущая скорость -->
		</joint>
		<joint name="right_wheel_joint">
			<command_interface name="velocity"/>
			<state_interface name="position"/>
			<state_interface name="velocity"/>
		</joint>
	</ros2_control>


</robot>
